Workbook

Sheet Customers
A1: customer_id | B1: first_name | C1: last_name | D1: email | E1: city | F1: state | G1: age | H1: gender | I1: join_date | J1: membership
A2: CUST-5001 | B2: Noah | C2: Brown | D2: user5001@email.com | E2: Phoenix | F2: AZ | G2: 25 | H2: Female | I2: 2022-04-16 | J2: Platinum
A3: CUST-5002 | B3: Sophia | C3: Wilson | D3: user5002@email.com | E3: San Jose | F3: CA | G3: 18 | H3: Female | I3: 2021-03-01 | J3: Gold
A4: CUST-5003 | B4: Sophia | C4: Miller | D4: user5003@email.com | E4: San Diego | F4: CA | G4: 29 | H4: Female | I4: 2021-04-11 | J4: Free
A5: CUST-5004 | B5: James | C5: Brown | D5: user5004@email.com | E5: Dallas | F5: TX | G5: 32 | H5: Male | I5: 2022-09-03 | J5: Free
A6: CUST-5005 | B6: Sophia | C6: Johnson | D6: user5005@email.com | E6: Houston | F6: TX | G6: 24 | H6: Male | I6: 2023-10-24 | J6: Free
A7: CUST-5006 | B7: James | C7: Johnson | D7: user5006@email.com | E7: Los Angeles | F7: CA | G7: 52 | H7: Male | I7: 2020-10-09 | J7: Free
A8: CUST-5007 | B8: Sophia | C8: Smith | D8: user5007@email.com | E8: Dallas | F8: TX | G8: 43 | H8: Male | I8: 2020-06-08 | J8: Silver
A9: CUST-5008 | B9: Emma | C9: Smith | D9: user5008@email.com | E9: San Antonio | F9: TX | G9: 21 | H9: Female | I9: 2021-07-21 | J9: Free
A10: CUST-5009 | B10: Ava | C10: Wilson | D10: user5009@email.com | E10: Philadelphia | F10: PA | G10: 54 | H10: Female | I10: 2023-02-02 | J10: Silver
A11: CUST-5010 | B11: Ava | C11: Wilson | D11: user5010@email.com | E11: Jacksonville | F11: FL | G11: 23 | H11: Male | I11: 2020-03-27 | J11: Free
A12: CUST-5011 | B12: Emma | C12: Smith | D12: user5011@email.com | E12: Philadelphia | F12: PA | G12: 48 | H12: Male | I12: 2023-10-25 | J12: Gold
A13: CUST-5012 | B13: Liam | C13: Davis | D13: user5012@email.com | E13: New York | F13: NY | G13: 25 | H13: Female | I13: 2020-04-16 | J13: Free
... A201: CUST-5200 | B201: Ava | C201: Garcia | D201: user5200@email.com | E201: Austin | F201: TX | G201: 64 | H201: Female | I201: 2021-12-20 | J201: Silver

Sheet Orders
A1: order_id | B1: customer_id | C1: order_date | D1: category | E1: product_name | F1: unit_price | G1: quantity | H1: discount_pct | I1: final_price | J1: order_total | K1: payment_method | L1: order_status | M1: rating
A2: ORD-20001 | B2: CUST-5001 | C2: 2024-02-27 | D2: Books | E2: Business Analytics | F2: 39.99 | G2: 1 | H2: 0 | I2: 39.99 | J2: 39.99 | K2: PayPal | L2: Delivered | M2: 4
A3: ORD-20002 | B3: CUST-5001 | C3: 2024-03-19 | D3: Toys | E3: Action Figure | F3: 19.99 | G3: 2 | H3: 0 | I3: 19.99 | J3: 39.98 | K3: Wallet | L3: Delivered | M3: 5
A4: ORD-20003 | B4: CUST-5001 | C4: 2022-01-05 | D4: Toys | E4: Puzzle 1000pcs | F4: 24.99 | G4: 2 | H4: 15 | I4: 21.24 | J4: 42.48 | K4: Wallet | L4: Delivered | M4: 5
A5: ORD-20004 | B5: CUST-5001 | C5: 2022-11-14 | D5: Home & Kitchen | E5: Blender | F5: 64.99 | G5: 3 | H5: 0 | I5: 64.99 | J5: 194.97 | K5: Credit Card | L5: Delivered
A6: ORD-20005 | B6: CUST-5001 | C6: 2024-07-01 | D6: Clothing | E6: Cotton T-Shirt | F6: 24.99 | G6: 4 | H6: 0 | I6: 24.99 | J6: 99.96 | K6: Credit Card | L6: Delivered | M6: 4
A7: ORD-20006 | B7: CUST-5001 | C7: 2023-05-11 | D7: Home & Kitchen | E7: Blender | F7: 64.99 | G7: 2 | H7: 5 | I7: 61.74 | J7: 123.48 | K7: UPI | L7: Delivered | M7: 5
A8: ORD-20007 | B8: CUST-5002 | C8: 2023-09-10 | D8: Home & Kitchen | E8: Blender | F8: 64.99 | G8: 1 | H8: 15 | I8: 55.24 | J8: 55.24 | K8: PayPal | L8: Delivered
A9: ORD-20008 | B9: CUST-5003 | C9: 2022-08-20 | D9: Sports | E9: Resistance Bands | F9: 19.99 | G9: 3 | H9: 0 | I9: 19.99 | J9: 59.97 | K9: Debit Card | L9: Delivered | M9: 5
A10: ORD-20009 | B10: CUST-5003 | C10: 2022-06-04 | D10: Electronics | E10: Bluetooth Speaker | F10: 49.99 | G10: 4 | H10: 5 | I10: 47.49 | J10: 189.96 | K10: UPI | L10: Delivered
A11: ORD-20010 | B11: CUST-5003 | C11: 2023-07-16 | D11: Sports | E11: Yoga Mat | F11: 29.99 | G11: 3 | H11: 15 | I11: 25.49 | J11: 76.47 | K11: UPI | L11: Delivered | M11: 4
A12: ORD-20011 | B12: CUST-5003 | C12: 2023-07-26 | D12: Sports | E12: Resistance Bands | F12: 19.99 | G12: 3 | H12: 0 | I12: 19.99 | J12: 59.97 | K12: UPI | L12: Delivered | M12: 5
A13: ORD-20012 | B13: CUST-5003 | C13: 2023-01-05 | D13: Toys | E13: Puzzle 1000pcs | F13: 24.99 | G13: 1 | H13: 10 | I13: 22.49 | J13: 22.49 | K13: PayPal | L13: Cancelled | M13: 3
A14: ORD-20013 | B14: CUST-5003 | C14: 2022-03-01 | D14: Home & Kitchen | E14: Coffee Maker | F14: 59.99 | G14: 4 | H14: 0 | I14: 59.99 | J14: 239.96 | K14: UPI | L14: Delivered | M14: 5
A15: ORD-20014 | B15: CUST-5003 | C15: 2022-06-24 | D15: Home & Kitchen | E15: Air Fryer | F15: 89.99 | G15: 1 | H15: 5 | I15: 85.49 | J15: 85.49 | K15: Wallet | L15: Delivered | M15: 5
A16: ORD-20015 | B16: CUST-5003 | C16: 2022-03-17 | D16: Electronics | E16: Smart Watch | F16: 199.99 | G16: 3 | H16: 10 | I16: 179.99 | J16: 539.97 | K16: Credit Card | L16: Delivered
A17: ORD-20016 | B17: CUST-5003 | C17: 2022-04-06 | D17: Electronics | E17: Wireless Earbuds | F17: 79.99 | G17: 1 | H17: 5 | I17: 75.99 | J17: 75.99 | K17: PayPal | L17: Delivered | M17: 5
A18: ORD-20017 | B18: CUST-5003 | C18: 2023-10-11 | D18: Sports | E18: Water Bottle | F18: 24.99 | G18: 3 | H18: 20 | I18: 19.99 | J18: 59.97 | K18: Wallet | L18: Delivered
A19: ORD-20018 | B19: CUST-5003 | C19: 2023-12-02 | D19: Beauty | E19: Lip Balm Set | F19: 14.99 | G19: 3 | H19: 5 | I19: 14.24 | J19: 42.72 | K19: Credit Card | L19: Delivered | M19: 4
A20: ORD-20019 | B20: CUST-5004 | C20: 2024-07-11 | D20: Home & Kitchen | E20: Non-stick Pan Set | F20: 44.99 | G20: 1 | H20: 20 | I20: 35.99 | J20: 35.99 | K20: PayPal | L20: Delivered | M20: 5
A21: ORD-20020 | B21: CUST-5004 | C21: 2023-01-23 | D21: Home & Kitchen | E21: Coffee Maker | F21: 59.99 | G21: 2 | H21: 0 | I21: 59.99 | J21: 119.98 | K21: Debit Card | L21: Delivered | M21: 5
A22: ORD-20021 | B22: CUST-5004 | C22: 2022-03-22 | D22: Home & Kitchen | E22: Non-stick Pan Set | F22: 44.99 | G22: 4 | H22: 15 | I22: 38.24 | J22: 152.96 | K22: Credit Card | L22: Delivered | M22: 5
A23: ORD-20022 | B23: CUST-5004 | C23: 2024-09-19 | D23: Beauty | E23: Hair Mask | F23: 24.99 | G23: 4 | H23: 0 | I23: 24.99 | J23: 99.96 | K23: Credit Card | L23: Delivered | M23: 1
A24: ORD-20023 | B24: CUST-5004 | C24: 2024-03-16 | D24: Clothing | E24: Running Shoes | F24: 89.99 | G24: 2 | H24: 10 | I24: 80.99 | J24: 161.98 | K24: UPI | L24: Delivered | M24: 4
A25: ORD-20024 | B25: CUST-5004 | C25: 2024-11-07 | D25: Books | E25: Fiction Novel | F25: 14.99 | G25: 1 | H25: 10 | I25: 13.49 | J25: 13.49 | K25: Credit Card | L25: Delivered | M25: 5
A26: ORD-20025 | B26: CUST-5004 | C26: 2023-01-20 | D26: Beauty | E26: Face Serum | F26: 39.99 | G26: 4 | H26: 10 | I26: 35.99 | J26: 143.96 | K26: Wallet | L26: Delivered
A27: ORD-20026 | B27: CUST-5004 | C27: 2024-03-13 | D27: Beauty | E27: Hair Mask | F27: 24.99 | G27: 2 | H27: 15 | I27: 21.24 | J27: 42.48 | K27: Wallet | L27: Delivered | M27: 4
A28: ORD-20027 | B28: CUST-5004 | C28: 2022-02-27 | D28: Clothing | E28: Yoga Pants | F28: 44.99 | G28: 2 | H28: 5 | I28: 42.74 | J28: 85.48 | K28: UPI | L28: Delivered | M28: 3
A29: ORD-20028 | B29: CUST-5004 | C29: 2022-03-01 | D29: Clothing | E29: Yoga Pants | F29: 44.99 | G29: 1 | H29: 0 | I29: 44.99 | J29: 44.99 | K29: Debit Card | L29: Delivered | M29: 5
A30: ORD-20029 | B30: CUST-5004 | C30: 2023-04-12 | D30: Beauty | E30: Face Serum | F30: 39.99 | G30: 3 | H30: 20 | I30: 31.99 | J30: 95.97 | K30: Credit Card | L30: Processing
A31: ORD-20030 | B31: CUST-5004 | C31: 2023-06-16 | D31: Electronics | E31: Smart Watch | F31: 199.99 | G31: 4 | H31: 20 | I31: 159.99 | J31: 639.96 | K31: UPI | L31: Delivered | M31: 5
A32: ORD-20031 | B32: CUST-5004 | C32: 2022-10-06 | D32: Toys | E32: Action Figure | F32: 19.99 | G32: 4 | H32: 0 | I32: 19.99 | J32: 79.96 | K32: Debit Card | L32: Delivered | M32: 5
A33: ORD-20032 | B33: CUST-5005 | C33: 2023-10-10 | D33: Beauty | E33: Moisturizer SPF 50 | F33: 29.99 | G33: 3 | H33: 20 | I33: 23.99 | J33: 71.97 | K33: Wallet | L33: Delivered
A34: ORD-20033 | B34: CUST-5005 | C34: 2024-10-10 | D34: Clothing | E34: Running Shoes | F34: 89.99 | G34: 1 | H34: 0 | I34: 89.99 | J34: 89.99 | K34: UPI | L34: Delivered | M34: 5
A35: ORD-20034 | B35: CUST-5005 | C35: 2022-09-11 | D35: Sports | E35: Jump Rope | F35: 14.99 | G35: 2 | H35: 0 | I35: 14.99 | J35: 29.98 | K35: Credit Card | L35: Delivered | M35: 3
A36: ORD-20035 | B36: CUST-5005 | C36: 2022-11-13 | D36: Books | E36: Fiction Novel | F36: 14.99 | G36: 1 | H36: 15 | I36: 12.74 | J36: 12.74 | K36: UPI | L36: Delivered | M36: 5
A37: ORD-20036 | B37: CUST-5005 | C37: 2023-10-21 | D37: Beauty | E37: Moisturizer SPF 50 | F37: 29.99 | G37: 1 | H37: 20 | I37: 23.99 | J37: 23.99 | K37: PayPal | L37: Delivered | M37: 3
A38: ORD-20037 | B38: CUST-5005 | C38: 2024-10-14 | D38: Home & Kitchen | E38: Air Fryer | F38: 89.99 | G38: 2 | H38: 20 | I38: 71.99 | J38: 143.98 | K38: Debit Card | L38: Delivered | M38: 5
A39: ORD-20038 | B39: CUST-5005 | C39: 2023-01-13 | D39: Electronics | E39: Bluetooth Speaker | F39: 49.99 | G39: 1 | H39: 15 | I39: 42.49 | J39: 42.49 | K39: Wallet | L39: Delivered
A40: ORD-20039 | B40: CUST-5005 | C40: 2023-03-24 | D40: Electronics | E40: Wireless Earbuds | F40: 79.99 | G40: 3 | H40: 5 | I40: 75.99 | J40: 227.97 | K40: Wallet | L40: Delivered | M40: 5
...

Sheet Master
A1: order_id | B1: customer_id | C1: order_date | D1: category | E1: product_name | F1: unit_price | G1: quantity | H1: discount_pct | I1: final_price | J1: order_total | K1: payment_method | L1: order_status | M1: rating | N1: Customer Age | O1: Customer City | P1: Membership | Q1: Gender | R1: Date_Check | S1: Month_Start
A2: ORD-20001 | B2: CUST-5001 | C2: 45349 | D2: Books | E2: Business Analytics | F2: 39.99 | G2: 1 | H2: 0 | I2: 39.99 | J2: 39.99 | K2: PayPal | L2: Delivered | M2: 4 | N2: =VLOOKUP(B2,Customers!A:J,7,0) -> 25 | O2: =VLOOKUP(B2,Customers!A:J,5,0) -> Phoenix | P2: =VLOOKUP(B2,Customers!A:J,10,0) -> Platinum | Q2: =VLOOKUP(B2,Customers!A:J,8,0) -> Female | R2: =ISNUMBER(C2) -> TRUE | S2: =DATE(YEAR(C2),MONTH(C2),1) -> 45323
A3: ORD-20002 | B3: CUST-5001 | C3: 45370 | D3: Toys | E3: Action Figure | F3: 19.99 | G3: 2 | H3: 0 | I3: 19.99 | J3: 39.98 | K3: Wallet | L3: Delivered | M3: 5 | N3: =VLOOKUP(B3,Customers!A:J,7,0) -> 25 | O3: =VLOOKUP(B3,Customers!A:J,5,0) -> Phoenix | P3: =VLOOKUP(B3,Customers!A:J,10,0) -> Platinum | Q3: =VLOOKUP(B3,Customers!A:J,8,0) -> Female | R3: =ISNUMBER(C3) -> TRUE | S3: =DATE(YEAR(C3),MONTH(C3),1) -> 45352
A4: ORD-20003 | B4: CUST-5001 | C4: 44566 | D4: Toys | E4: Puzzle 1000pcs | F4: 24.99 | G4: 2 | H4: 15 | I4: 21.24 | J4: 42.48 | K4: Wallet | L4: Delivered | M4: 5 | N4: =VLOOKUP(B4,Customers!A:J,7,0) -> 25 | O4: =VLOOKUP(B4,Customers!A:J,5,0) -> Phoenix | P4: =VLOOKUP(B4,Customers!A:J,10,0) -> Platinum | Q4: =VLOOKUP(B4,Customers!A:J,8,0) -> Female | R4: =ISNUMBER(C4) -> TRUE | S4: =DATE(YEAR(C4),MONTH(C4),1) -> 44562
A5: ORD-20004 | B5: CUST-5001 | C5: 44879 | D5: Home & Kitchen | E5: Blender | F5: 64.99 | G5: 3 | H5: 0 | I5: 64.99 | J5: 194.97 | K5: Credit Card | L5: Delivered | N5: =VLOOKUP(B5,Customers!A:J,7,0) -> 25 | O5: =VLOOKUP(B5,Customers!A:J,5,0) -> Phoenix | P5: =VLOOKUP(B5,Customers!A:J,10,0) -> Platinum | Q5: =VLOOKUP(B5,Customers!A:J,8,0) -> Female | R5: =ISNUMBER(C5) -> TRUE | S5: =DATE(YEAR(C5),MONTH(C5),1) -> 44866
A6: ORD-20005 | B6: CUST-5001 | C6: 45474 | D6: Clothing | E6: Cotton T-Shirt | F6: 24.99 | G6: 4 | H6: 0 | I6: 24.99 | J6: 99.96 | K6: Credit Card | L6: Delivered | M6: 4 | N6: =VLOOKUP(B6,Customers!A:J,7,0) -> 25 | O6: =VLOOKUP(B6,Customers!A:J,5,0) -> Phoenix | P6: =VLOOKUP(B6,Customers!A:J,10,0) -> Platinum | Q6: =VLOOKUP(B6,Customers!A:J,8,0) -> Female | R6: =ISNUMBER(C6) -> TRUE | S6: =DATE(YEAR(C6),MONTH(C6),1) -> 45474
A7: ORD-20006 | B7: CUST-5001 | C7: 45057 | D7: Home & Kitchen | E7: Blender | F7: 64.99 | G7: 2 | H7: 5 | I7: 61.74 | J7: 123.48 | K7: UPI | L7: Delivered | M7: 5 | N7: =VLOOKUP(B7,Customers!A:J,7,0) -> 25 | O7: =VLOOKUP(B7,Customers!A:J,5,0) -> Phoenix | P7: =VLOOKUP(B7,Customers!A:J,10,0) -> Platinum | Q7: =VLOOKUP(B7,Customers!A:J,8,0) -> Female | R7: =ISNUMBER(C7) -> TRUE | S7: =DATE(YEAR(C7),MONTH(C7),1) -> 45047
A8: ORD-20007 | B8: CUST-5002 | C8: 45179 | D8: Home & Kitchen | E8: Blender | F8: 64.99 | G8: 1 | H8: 15 | I8: 55.24 | J8: 55.24 | K8: PayPal | L8: Delivered | N8: =VLOOKUP(B8,Customers!A:J,7,0) -> 18 | O8: =VLOOKUP(B8,Customers!A:J,5,0) -> San Jose | P8: =VLOOKUP(B8,Customers!A:J,10,0) -> Gold | Q8: =VLOOKUP(B8,Customers!A:J,8,0) -> Female | R8: =ISNUMBER(C8) -> TRUE | S8: =DATE(YEAR(C8),MONTH(C8),1) -> 45170
A9: ORD-20008 | B9: CUST-5003 | C9: 44793 | D9: Sports | E9: Resistance Bands | F9: 19.99 | G9: 3 | H9: 0 | I9: 19.99 | J9: 59.97 | K9: Debit Card | L9: Delivered | M9: 5 | N9: =VLOOKUP(B9,Customers!A:J,7,0) -> 29 | O9: =VLOOKUP(B9,Customers!A:J,5,0) -> San Diego | P9: =VLOOKUP(B9,Customers!A:J,10,0) -> Free | Q9: =VLOOKUP(B9,Customers!A:J,8,0) -> Female | R9: =ISNUMBER(C9) -> TRUE | S9: =DATE(YEAR(C9),MONTH(C9),1) -> 44774
A10: ORD-20009 | B10: CUST-5003 | C10: 44716 | D10: Electronics | E10: Bluetooth Speaker | F10: 49.99 | G10: 4 | H10: 5 | I10: 47.49 | J10: 189.96 | K10: UPI | L10: Delivered | N10: =VLOOKUP(B10,Customers!A:J,7,0) -> 29 | O10: =VLOOKUP(B10,Customers!A:J,5,0) -> San Diego | P10: =VLOOKUP(B10,Customers!A:J,10,0) -> Free | Q10: =VLOOKUP(B10,Customers!A:J,8,0) -> Female | R10: =ISNUMBER(C10) -> TRUE | S10: =DATE(YEAR(C10),MONTH(C10),1) -> 44713
A11: ORD-20010 | B11: CUST-5003 | C11: 45123 | D11: Sports | E11: Yoga Mat | F11: 29.99 | G11: 3 | H11: 15 | I11: 25.49 | J11: 76.47 | K11: UPI | L11: Delivered | M11: 4 | N11: =VLOOKUP(B11,Customers!A:J,7,0) -> 29 | O11: =VLOOKUP(B11,Customers!A:J,5,0) -> San Diego | P11: =VLOOKUP(B11,Customers!A:J,10,0) -> Free | Q11: =VLOOKUP(B11,Customers!A:J,8,0) -> Female | R11: =ISNUMBER(C11) -> TRUE | S11: =DATE(YEAR(C11),MONTH(C11),1) -> 45108
A12: ORD-20011 | B12: CUST-5003 | C12: 45133 | D12: Sports | E12: Resistance Bands | F12: 19.99 | G12: 3 | H12: 0 | I12: 19.99 | J12: 59.97 | K12: UPI | L12: Delivered | M12: 5 | N12: =VLOOKUP(B12,Customers!A:J,7,0) -> 29 | O12: =VLOOKUP(B12,Customers!A:J,5,0) -> San Diego | P12: =VLOOKUP(B12,Customers!A:J,10,0) -> Free | Q12: =VLOOKUP(B12,Customers!A:J,8,0) -> Female | R12: =ISNUMBER(C12) -> TRUE | S12: =DATE(YEAR(C12),MONTH(C12),1) -> 45108
A13: ORD-20012 | B13: CUST-5003 | C13: 44931 | D13: Toys | E13: Puzzle 1000pcs | F13: 24.99 | G13: 1 | H13: 10 | I13: 22.49 | J13: 22.49 | K13: PayPal | L13: Cancelled | M13: 3 | N13: =VLOOKUP(B13,Customers!A:J,7,0) -> 29 | O13: =VLOOKUP(B13,Customers!A:J,5,0) -> San Diego | P13: =VLOOKUP(B13,Customers!A:J,10,0) -> Free | Q13: =VLOOKUP(B13,Customers!A:J,8,0) -> Female | R13: =ISNUMBER(C13) -> TRUE | S13: =DATE(YEAR(C13),MONTH(C13),1) -> 44927
A14: ORD-20013 | B14: CUST-5003 | C14: 44621 | D14: Home & Kitchen | E14: Coffee Maker | F14: 59.99 | G14: 4 | H14: 0 | I14: 59.99 | J14: 239.96 | K14: UPI | L14: Delivered | M14: 5 | N14: =VLOOKUP(B14,Customers!A:J,7,0) -> 29 | O14: =VLOOKUP(B14,Customers!A:J,5,0) -> San Diego | P14: =VLOOKUP(B14,Customers!A:J,10,0) -> Free | Q14: =VLOOKUP(B14,Customers!A:J,8,0) -> Female | R14: =ISNUMBER(C14) -> TRUE | S14: =DATE(YEAR(C14),MONTH(C14),1) -> 44621
A15: ORD-20014 | B15: CUST-5003 | C15: 44736 | D15: Home & Kitchen | E15: Air Fryer | F15: 89.99 | G15: 1 | H15: 5 | I15: 85.49 | J15: 85.49 | K15: Wallet | L15: Delivered | M15: 5 | N15: =VLOOKUP(B15,Customers!A:J,7,0) -> 29 | O15: =VLOOKUP(B15,Customers!A:J,5,0) -> San Diego | P15: =VLOOKUP(B15,Customers!A:J,10,0) -> Free | Q15: =VLOOKUP(B15,Customers!A:J,8,0) -> Female | R15: =ISNUMBER(C15) -> TRUE | S15: =DATE(YEAR(C15),MONTH(C15),1) -> 44713
A16: ORD-20015 | B16: CUST-5003 | C16: 44637 | D16: Electronics | E16: Smart Watch | F16: 199.99 | G16: 3 | H16: 10 | I16: 179.99 | J16: 539.97 | K16: Credit Card | L16: Delivered | N16: =VLOOKUP(B16,Customers!A:J,7,0) -> 29 | O16: =VLOOKUP(B16,Customers!A:J,5,0) -> San Diego | P16: =VLOOKUP(B16,Customers!A:J,10,0) -> Free | Q16: =VLOOKUP(B16,Customers!A:J,8,0) -> Female | R16: =ISNUMBER(C16) -> TRUE | S16: =DATE(YEAR(C16),MONTH(C16),1) -> 44621
A17: ORD-20016 | B17: CUST-5003 | C17: 44657 | D17: Electronics | E17: Wireless Earbuds | F17: 79.99 | G17: 1 | H17: 5 | I17: 75.99 | J17: 75.99 | K17: PayPal | L17: Delivered | M17: 5 | N17: =VLOOKUP(B17,Customers!A:J,7,0) -> 29 | O17: =VLOOKUP(B17,Customers!A:J,5,0) -> San Diego | P17: =VLOOKUP(B17,Customers!A:J,10,0) -> Free | Q17: =VLOOKUP(B17,Customers!A:J,8,0) -> Female | R17: =ISNUMBER(C17) -> TRUE | S17: =DATE(YEAR(C17),MONTH(C17),1) -> 44652
A18: ORD-20017 | B18: CUST-5003 | C18: 45210 | D18: Sports | E18: Water Bottle | F18: 24.99 | G18: 3 | H18: 20 | I18: 19.99 | J18: 59.97 | K18: Wallet | L18: Delivered | N18: =VLOOKUP(B18,Customers!A:J,7,0) -> 29 | O18: =VLOOKUP(B18,Customers!A:J,5,0) -> San Diego | P18: =VLOOKUP(B18,Customers!A:J,10,0) -> Free | Q18: =VLOOKUP(B18,Customers!A:J,8,0) -> Female | R18: =ISNUMBER(C18) -> TRUE | S18: =DATE(YEAR(C18),MONTH(C18),1) -> 45200
A19: ORD-20018 | B19: CUST-5003 | C19: 45262 | D19: Beauty | E19: Lip Balm Set | F19: 14.99 | G19: 3 | H19: 5 | I19: 14.24 | J19: 42.72 | K19: Credit Card | L19: Delivered | M19: 4 | N19: =VLOOKUP(B19,Customers!A:J,7,0) -> 29 | O19: =VLOOKUP(B19,Customers!A:J,5,0) -> San Diego | P19: =VLOOKUP(B19,Customers!A:J,10,0) -> Free | Q19: =VLOOKUP(B19,Customers!A:J,8,0) -> Female | R19: =ISNUMBER(C19) -> TRUE | S19: =DATE(YEAR(C19),MONTH(C19),1) -> 45261
A20: ORD-20019 | B20: CUST-5004 | C20: 45484 | D20: Home & Kitchen | E20: Non-stick Pan Set | F20: 44.99 | G20: 1 | H20: 20 | I20: 35.99 | J20: 35.99 | K20: PayPal | L20: Delivered | M20: 5 | N20: =VLOOKUP(B20,Customers!A:J,7,0) -> 32 | O20: =VLOOKUP(B20,Customers!A:J,5,0) -> Dallas | P20: =VLOOKUP(B20,Customers!A:J,10,0) -> Free | Q20: =VLOOKUP(B20,Customers!A:J,8,0) -> Male | R20: =ISNUMBER(C20) -> TRUE | S20: =DATE(YEAR(C20),MONTH(C20),1) -> 45474
A21: ORD-20020 | B21: CUST-5004 | C21: 44949 | D21: Home & Kitchen | E21: Coffee Maker | F21: 59.99 | G21: 2 | H21: 0 | I21: 59.99 | J21: 119.98 | K21: Debit Card | L21: Delivered | M21: 5 | N21: =VLOOKUP(B21,Customers!A:J,7,0) -> 32 | O21: =VLOOKUP(B21,Customers!A:J,5,0) -> Dallas | P21: =VLOOKUP(B21,Customers!A:J,10,0) -> Free | Q21: =VLOOKUP(B21,Customers!A:J,8,0) -> Male | R21: =ISNUMBER(C21) -> TRUE | S21: =DATE(YEAR(C21),MONTH(C21),1) -> 44927
A22: ORD-20021 | B22: CUST-5004 | C22: 44642 | D22: Home & Kitchen | E22: Non-stick Pan Set | F22: 44.99 | G22: 4 | H22: 15 | I22: 38.24 | J22: 152.96 | K22: Credit Card | L22: Delivered | M22: 5 | N22: =VLOOKUP(B22,Customers!A:J,7,0) -> 32 | O22: =VLOOKUP(B22,Customers!A:J,5,0) -> Dallas | P22: =VLOOKUP(B22,Customers!A:J,10,0) -> Free | Q22: =VLOOKUP(B22,Customers!A:J,8,0) -> Male | R22: =ISNUMBER(C22) -> TRUE | S22: =DATE(YEAR(C22),MONTH(C22),1) -> 44621
A23: ORD-20022 | B23: CUST-5004 | C23: 45554 | D23: Beauty | E23: Hair Mask | F23: 24.99 | G23: 4 | H23: 0 | I23: 24.99 | J23: 99.96 | K23: Credit Card | L23: Delivered | M23: 1 | N23: =VLOOKUP(B23,Customers!A:J,7,0) -> 32 | O23: =VLOOKUP(B23,Customers!A:J,5,0) -> Dallas | P23: =VLOOKUP(B23,Customers!A:J,10,0) -> Free | Q23: =VLOOKUP(B23,Customers!A:J,8,0) -> Male | R23: =ISNUMBER(C23) -> TRUE | S23: =DATE(YEAR(C23),MONTH(C23),1) -> 45536
A24: ORD-20023 | B24: CUST-5004 | C24: 45367 | D24: Clothing | E24: Running Shoes | F24: 89.99 | G24: 2 | H24: 10 | I24: 80.99 | J24: 161.98 | K24: UPI | L24: Delivered | M24: 4 | N24: =VLOOKUP(B24,Customers!A:J,7,0) -> 32 | O24: =VLOOKUP(B24,Customers!A:J,5,0) -> Dallas | P24: =VLOOKUP(B24,Customers!A:J,10,0) -> Free | Q24: =VLOOKUP(B24,Customers!A:J,8,0) -> Male | R24: =ISNUMBER(C24) -> TRUE | S24: =DATE(YEAR(C24),MONTH(C24),1) -> 45352
A25: ORD-20024 | B25: CUST-5004 | C25: 45603 | D25: Books | E25: Fiction Novel | F25: 14.99 | G25: 1 | H25: 10 | I25: 13.49 | J25: 13.49 | K25: Credit Card | L25: Delivered | M25: 5 | N25: =VLOOKUP(B25,Customers!A:J,7,0) -> 32 | O25: =VLOOKUP(B25,Customers!A:J,5,0) -> Dallas | P25: =VLOOKUP(B25,Customers!A:J,10,0) -> Free | Q25: =VLOOKUP(B25,Customers!A:J,8,0) -> Male | R25: =ISNUMBER(C25) -> TRUE | S25: =DATE(YEAR(C25),MONTH(C25),1) -> 45597
A26: ORD-20025 | B26: CUST-5004 | C26: 44946 | D26: Beauty | E26: Face Serum | F26: 39.99 | G26: 4 | H26: 10 | I26: 35.99 | J26: 143.96 | K26: Wallet | L26: Delivered | N26: =VLOOKUP(B26,Customers!A:J,7,0) -> 32 | O26: =VLOOKUP(B26,Customers!A:J,5,0) -> Dallas | P26: =VLOOKUP(B26,Customers!A:J,10,0) -> Free | Q26: =VLOOKUP(B26,Customers!A:J,8,0) -> Male | R26: =ISNUMBER(C26) -> TRUE | S26: =DATE(YEAR(C26),MONTH(C26),1) -> 44927
A27: ORD-20026 | B27: CUST-5004 | C27: 45364 | D27: Beauty | E27: Hair Mask | F27: 24.99 | G27: 2 | H27: 15 | I27: 21.24 | J27: 42.48 | K27: Wallet | L27: Delivered | M27: 4 | N27: =VLOOKUP(B27,Customers!A:J,7,0) -> 32 | O27: =VLOOKUP(B27,Customers!A:J,5,0) -> Dallas | P27: =VLOOKUP(B27,Customers!A:J,10,0) -> Free | Q27: =VLOOKUP(B27,Customers!A:J,8,0) -> Male | R27: =ISNUMBER(C27) -> TRUE | S27: =DATE(YEAR(C27),MONTH(C27),1) -> 45352
A28: ORD-20027 | B28: CUST-5004 | C28: 44619 | D28: Clothing | E28: Yoga Pants | F28: 44.99 | G28: 2 | H28: 5 | I28: 42.74 | J28: 85.48 | K28: UPI | L28: Delivered | M28: 3 | N28: =VLOOKUP(B28,Customers!A:J,7,0) -> 32 | O28: =VLOOKUP(B28,Customers!A:J,5,0) -> Dallas | P28: =VLOOKUP(B28,Customers!A:J,10,0) -> Free | Q28: =VLOOKUP(B28,Customers!A:J,8,0) -> Male | R28: =ISNUMBER(C28) -> TRUE | S28: =DATE(YEAR(C28),MONTH(C28),1) -> 44593
A29: ORD-20028 | B29: CUST-5004 | C29: 44621 | D29: Clothing | E29: Yoga Pants | F29: 44.99 | G29: 1 | H29: 0 | I29: 44.99 | J29: 44.99 | K29: Debit Card | L29: Delivered | M29: 5 | N29: =VLOOKUP(B29,Customers!A:J,7,0) -> 32 | O29: =VLOOKUP(B29,Customers!A:J,5,0) -> Dallas | P29: =VLOOKUP(B29,Customers!A:J,10,0) -> Free | Q29: =VLOOKUP(B29,Customers!A:J,8,0) -> Male | R29: =ISNUMBER(C29) -> TRUE | S29: =DATE(YEAR(C29),MONTH(C29),1) -> 44621
A30: ORD-20029 | B30: CUST-5004 | C30: 45028 | D30: Beauty | E30: Face Serum | F30: 39.99 | G30: 3 | H30: 20 | I30: 31.99 | J30: 95.97 | K30: Credit Card | L30: Processing | N30: =VLOOKUP(B30,Customers!A:J,7,0) -> 32 | O30: =VLOOKUP(B30,Customers!A:J,5,0) -> Dallas | P30: =VLOOKUP(B30,Customers!A:J,10,0) -> Free | Q30: =VLOOKUP(B30,Customers!A:J,8,0) -> Male | R30: =ISNUMBER(C30) -> TRUE | S30: =DATE(YEAR(C30),MONTH(C30),1) -> 45017
A31: ORD-20030 | B31: CUST-5004 | C31: 45093 | D31: Electronics | E31: Smart Watch | F31: 199.99 | G31: 4 | H31: 20 | I31: 159.99 | J31: 639.96 | K31: UPI | L31: Delivered | M31: 5 | N31: =VLOOKUP(B31,Customers!A:J,7,0) -> 32 | O31: =VLOOKUP(B31,Customers!A:J,5,0) -> Dallas | P31: =VLOOKUP(B31,Customers!A:J,10,0) -> Free | Q31: =VLOOKUP(B31,Customers!A:J,8,0) -> Male | R31: =ISNUMBER(C31) -> TRUE | S31: =DATE(YEAR(C31),MONTH(C31),1) -> 45078
A32: ORD-20031 | B32: CUST-5004 | C32: 44840 | D32: Toys | E32: Action Figure | F32: 19.99 | G32: 4 | H32: 0 | I32: 19.99 | J32: 79.96 | K32: Debit Card | L32: Delivered | M32: 5 | N32: =VLOOKUP(B32,Customers!A:J,7,0) -> 32 | O32: =VLOOKUP(B32,Customers!A:J,5,0) -> Dallas | P32: =VLOOKUP(B32,Customers!A:J,10,0) -> Free | Q32: =VLOOKUP(B32,Customers!A:J,8,0) -> Male | R32: =ISNUMBER(C32) -> TRUE | S32: =DATE(YEAR(C32),MONTH(C32),1) -> 44835
A33: ORD-20032 | B33: CUST-5005 | C33: 45209 | D33: Beauty | E33: Moisturizer SPF 50 | F33: 29.99 | G33: 3 | H33: 20 | I33: 23.99 | J33: 71.97 | K33: Wallet | L33: Delivered | N33: =VLOOKUP(B33,Customers!A:J,7,0) -> 24 | O33: =VLOOKUP(B33,Customers!A:J,5,0) -> Houston | P33: =VLOOKUP(B33,Customers!A:J,10,0) -> Free | Q33: =VLOOKUP(B33,Customers!A:J,8,0) -> Male | R33: =ISNUMBER(C33) -> TRUE | S33: =DATE(YEAR(C33),MONTH(C33),1) -> 45200
A34: ORD-20033 | B34: CUST-5005 | C34: 45575 | D34: Clothing | E34: Running Shoes | F34: 89.99 | G34: 1 | H34: 0 | I34: 89.99 | J34: 89.99 | K34: UPI | L34: Delivered | M34: 5 | N34: =VLOOKUP(B34,Customers!A:J,7,0) -> 24 | O34: =VLOOKUP(B34,Customers!A:J,5,0) -> Houston | P34: =VLOOKUP(B34,Customers!A:J,10,0) -> Free | Q34: =VLOOKUP(B34,Customers!A:J,8,0) -> Male | R34: =ISNUMBER(C34) -> TRUE | S34: =DATE(YEAR(C34),MONTH(C34),1) -> 45566
A35: ORD-20034 | B35: CUST-5005 | C35: 44815 | D35: Sports | E35: Jump Rope | F35: 14.99 | G35: 2 | H35: 0 | I35: 14.99 | J35: 29.98 | K35: Credit Card | L35: Delivered | M35: 3 | N35: =VLOOKUP(B35,Customers!A:J,7,0) -> 24 | O35: =VLOOKUP(B35,Customers!A:J,5,0) -> Houston | P35: =VLOOKUP(B35,Customers!A:J,10,0) -> Free | Q35: =VLOOKUP(B35,Customers!A:J,8,0) -> Male | R35: =ISNUMBER(C35) -> TRUE | S35: =DATE(YEAR(C35),MONTH(C35),1) -> 44805
A36: ORD-20035 | B36: CUST-5005 | C36: 44878 | D36: Books | E36: Fiction Novel | F36: 14.99 | G36: 1 | H36: 15 | I36: 12.74 | J36: 12.74 | K36: UPI | L36: Delivered | M36: 5 | N36: =VLOOKUP(B36,Customers!A:J,7,0) -> 24 | O36: =VLOOKUP(B36,Customers!A:J,5,0) -> Houston | P36: =VLOOKUP(B36,Customers!A:J,10,0) -> Free | Q36: =VLOOKUP(B36,Customers!A:J,8,0) -> Male | R36: =ISNUMBER(C36) -> TRUE | S36: =DATE(YEAR(C36),MONTH(C36),1) -> 44866
A37: ORD-20036 | B37: CUST-5005 | C37: 45220 | D37: Beauty | E37: Moisturizer SPF 50 | F37: 29.99 | G37: 1 | H37: 20 | I37: 23.99 | J37: 23.99 | K37: PayPal | L37: Delivered | M37: 3 | N37: =VLOOKUP(B37,Customers!A:J,7,0) -> 24 | O37: =VLOOKUP(B37,Customers!A:J,5,0) -> Houston | P37: =VLOOKUP(B37,Customers!A:J,10,0) -> Free | Q37: =VLOOKUP(B37,Customers!A:J,8,0) -> Male | R37: =ISNUMBER(C37) -> TRUE | S37: =DATE(YEAR(C37),MONTH(C37),1) -> 45200
A38: ORD-20037 | B38: CUST-5005 | C38: 45579 | D38: Home & Kitchen | E38: Air Fryer | F38: 89.99 | G38: 2 | H38: 20 | I38: 71.99 | J38: 143.98 | K38: Debit Card | L38: Delivered | M38: 5 | N38: =VLOOKUP(B38,Customers!A:J,7,0) -> 24 | O38: =VLOOKUP(B38,Customers!A:J,5,0) -> Houston | P38: =VLOOKUP(B38,Customers!A:J,10,0) -> Free | Q38: =VLOOKUP(B38,Customers!A:J,8,0) -> Male | R38: =ISNUMBER(C38) -> TRUE | S38: =DATE(YEAR(C38),MONTH(C38),1) -> 45566
A39: ORD-20038 | B39: CUST-5005 | C39: 44939 | D39: Electronics | E39: Bluetooth Speaker | F39: 49.99 | G39: 1 | H39: 15 | I39: 42.49 | J39: 42.49 | K39: Wallet | L39: Delivered | N39: =VLOOKUP(B39,Customers!A:J,7,0) -> 24 | O39: =VLOOKUP(B39,Customers!A:J,5,0) -> Houston | P39: =VLOOKUP(B39,Customers!A:J,10,0) -> Free | Q39: =VLOOKUP(B39,Customers!A:J,8,0) -> Male | R39: =ISNUMBER(C39) -> TRUE | S39: =DATE(YEAR(C39),MONTH(C39),1) -> 44927
A40: ORD-20039 | B40: CUST-5005 | C40: 45009 | D40: Electronics | E40: Wireless Earbuds | F40: 79.99 | G40: 3 | H40: 5 | I40: 75.99 | J40: 227.97 | K40: Wallet | L40: Delivered | M40: 5 | N40: =VLOOKUP(B40,Customers!A:J,7,0) -> 24 | O40: =VLOOKUP(B40,Customers!A:J,5,0) -> Houston | P40: =VLOOKUP(B40,Customers!A:J,10,0) -> Free | Q40: =VLOOKUP(B40,Customers!A:J,8,0) -> Male | R40: =ISNUMBER(C40) -> TRUE | S40: =DATE(YEAR(C40),MONTH(C40),1) -> 44986
...

Sheet Pivot_Analysis
A1: rati | B1: Sum of order_total | C1: Count of order_id | D1: Average of rating | H1: Row Labels | I1: Sum of order_total | J1: Average of order_total2
A2: Electronics | B2: 46884.23 | C2: 225 | D2: 4.0066667 | H2: Free | I2: 91517.53 | J2: 109.73325
A3: Home & Kitchen | B3: 36312.97 | C3: 236 | D3: 4.0584795 | H3: Silver | I3: 50255.37 | J3: 104.26425
A4: Clothing | B4: 31322.64 | C4: 261 | D4: 4.0617978 | H4: Platinum | I4: 20797 | J4: 110.03704
A5: Toys | B5: 20328.98 | C5: 249 | D5: 4.1412429 | H5: Gold | I5: 16690.65 | J5: 112.01779
A6: Books | B6: 18687.63 | C6: 233 | D6: 4.2012195 | H6: Grand Total | I6: 179260.55 | J6: 108.38002
A7: Beauty | B7: 14108.7 | C7: 226 | D7: 4.1401274
A8: Sports | B8: 11615.4 | C8: 224 | D8: 4.054878
A9: Grand Total | B9: 179260.55 | C9: 1654 | D9: 4.0956072
B12: Total Revenue
A13: Row Labels | B13: Sum of order_total | C13: Count of order_id | F13: Row Labels | G13: Sum of order_total
A14: Delivered | B14: 154704.02 | C14: 1419 | F14: 2022 | G14: 62142.83
A15: Shipped | B15: 9942.93 | C15: 108 | F15: 2023 | G15: 58744.36
A16: Processing | B16: 8044.54 | C16: 64 | F16: 2024 | G16: 58373.36
A17: Returned | B17: 3440.76 | C17: 32 | F17: Grand Total | G17: 179260.55
A18: Cancelled | B18: 3128.3 | C18: 31
A19: Grand Total | B19: 179260.55 | C19: 1654
A22: Total Revenue | B22: Total Orders | C22: Avg Order Value | D22: Return Rate | E22: Top Category
A23: =SUMIF(Orders!L:L,"Delivered",Orders!J:J) -> 154704.02 | B23: =COUNTIF(Orders!L:L,"Delivered") -> 1419 | C23: =SUMIF(Orders!L:L,"Delivered",Orders!J:J)/COUNTIF(Orders!L:L,"Delivered") -> 109.02327 | D23: =COUNTIF(Orders!L:L,"Returned")/(COUNTA(Orders!A:A)-1)*100 -> 1.9347037 | E23: =INDEX(A2:A8,MATCH(MAX(B2:B8),B2:B8,0)) -> Electronics

Sheet Analysis_Guide
A1: Analysis Tasks for This Project
A3: 1. Customer Segmentation | B3: Segment customers by membership tier and analyze AOV, frequency
A4: 2. Cohort Retention | B4: Group customers by join quarter; track repeat purchase rates
A5: 3. Category Performance | B5: Revenue, units sold, avg discount, and return rate by category
A6: 4. Payment Method Trends | B6: Preferred payment by age group and membership tier
A7: 5. Rating vs Revenue | B7: Correlation between product ratings and repeat purchases
A8: 6. RFM Analysis | B8: Recency, Frequency, Monetary segmentation using SQL or Excel
A9: 7. Top Cities Dashboard | B9: Revenue by city on a Tableau map visualization
